{
  LOG.error("Unexpected exception, continuing.",e.getCause());
}
