{
  LOG.error("Unexpected exception, continuing.",cause);
}
